<?xml version="1.0" ?>
<!-- =================================================================================== -->
<!-- |    This document was autogenerated by xacro from robot.xacro                    | -->
<!-- |    EDITING THIS FILE BY HAND IS NOT RECOMMENDED                                 | -->
<!-- =================================================================================== -->
<robot name="swingboy_v1">
  <material name="black">
    <color rgba="0.0 0.0 0.0 1.0"/>
  </material>
  <material name="blue">
    <color rgba="0.0 0.0 0.8 1.0"/>
  </material>
  <material name="green">
    <color rgba="0.0 0.8 0.0 1.0"/>
  </material>
  <material name="grey">
    <color rgba="0.2 0.2 0.2 1.0"/>
  </material>
  <material name="silver">
    <color rgba="0.9137254901960784 0.9137254901960784 0.8470588235294118 1.0"/>
  </material>
  <material name="orange">
    <color rgba="1.0 0.4235294117647059 0.0392156862745098 1.0"/>
  </material>
  <material name="brown">
    <color rgba="0.8705882352941177 0.8117647058823529 0.7647058823529411 1.0"/>
  </material>
  <material name="red">
    <color rgba="0.8 0.0 0.0 1.0"/>
  </material>
  <material name="white">
    <color rgba="1.0 1.0 1.0 1.0"/>
  </material>
  <link name="world"/>
  <link name="base_link">
    <inertial>
      <origin rpy="0 0 0" xyz="0 0 0"/>
      <mass value="6.722505"/>
      <inertia ixx="5.0759999999999995e-05" ixy="-6.577244e-06" ixz="-6.089641e-06" iyy="3.9939999999999994e-05" iyz="4.160622e-06" izz="8.303e-05"/>
    </inertial>
    <visual>
      <origin rpy="0 0 0" xyz="0 0 0"/>
      <geometry>
        <mesh filename="package://swing_arm/description/meshes/base_link.stl"/>
      </geometry>
      <material name="silver"/>
    </visual>
    <collision>
      <origin rpy="0 0 0" xyz="0 0 0"/>
      <geometry>
        <mesh filename="package://swing_arm/description/meshes/base_link.stl"/>
      </geometry>
    </collision>
  </link>
  <link name="link1">
    <inertial>
      <origin rpy="0 0 0" xyz="0 0 0"/>
      <mass value="1.103721"/>
      <inertia ixx="0.001932" ixy="-4.3058e-05" ixz="-7.5977e-05" iyy="0.001823" iyz="0.00021619999999999997" izz="0.0005694"/>
    </inertial>
    <visual>
      <origin rpy="0 0 0" xyz="0 0 0"/>
      <geometry>
        <mesh filename="package://swing_arm/description/meshes/link1.stl"/>
      </geometry>
      <material name="silver"/>
    </visual>
    <collision>
      <origin rpy="0 0 0" xyz="0 0 0"/>
      <geometry>
        <mesh filename="package://swing_arm/description/meshes/link1.stl"/>
      </geometry>
    </collision>
  </link>
  <link name="link2">
    <inertial>
      <origin rpy="0 0 0" xyz="0 0 0"/>
      <mass value="1.125559"/>
      <inertia ixx="0.0006605" ixy="-0.00129" ixz="0.000314817" iyy="0.051519999999999996" iyz="-4.0039999999999996e-05" izz="0.051719999999999995"/>
    </inertial>
    <visual>
      <origin rpy="0 0 0" xyz="0 0 0"/>
      <geometry>
        <mesh filename="package://swing_arm/description/meshes/link2.stl"/>
      </geometry>
      <material name="silver"/>
    </visual>
    <collision>
      <origin rpy="0 0 0" xyz="0 0 0"/>
      <geometry>
        <mesh filename="package://swing_arm/description/meshes/link2.stl"/>
      </geometry>
    </collision>
  </link>
  <link name="link3">
    <inertial>
      <origin rpy="0 0 0" xyz="0 0 0"/>
      <mass value="1.014702"/>
      <inertia ixx="0.0036799999999999997" ixy="0.0009699999999999999" ixz="-0.01192" iyy="0.0491" iyz="0.0002528" izz="0.04602"/>
    </inertial>
    <visual>
      <origin rpy="0 0 0" xyz="0 0 0"/>
      <geometry>
        <mesh filename="package://swing_arm/description/meshes/link3.stl"/>
      </geometry>
      <material name="silver"/>
    </visual>
    <collision>
      <origin rpy="0 0 0" xyz="0 0 0"/>
      <geometry>
        <mesh filename="package://swing_arm/description/meshes/link3.stl"/>
      </geometry>
    </collision>
  </link>
  <link name="link4">
    <inertial>
      <origin rpy="0 0 0" xyz="0 0 0"/>
      <mass value="0.056678"/>
      <inertia ixx="2.067719e-05" ixy="3.4399999999999996e-07" ixz="-1.186835e-05" iyy="2.6497579999999997e-05" iyz="2.61e-07" izz="1.477608e-05"/>
    </inertial>
    <visual>
      <origin rpy="0 0 0" xyz="0 0 0"/>
      <geometry>
        <mesh filename="package://swing_arm/description/meshes/link4.stl"/>
      </geometry>
      <material name="silver"/>
    </visual>
    <collision>
      <origin rpy="0 0 0" xyz="0 0 0"/>
      <geometry>
        <mesh filename="package://swing_arm/description/meshes/link4.stl"/>
      </geometry>
    </collision>
  </link>
  <link name="link5">
    <inertial>
      <origin rpy="0 0 0" xyz="0 0 0"/>
      <mass value="1.784979"/>
      <inertia ixx="0.007235999999999999" ixy="0.00034058" ixz="0.038829999999999996" iyy="0.007231" iyz="0.0040669059999999995" izz="0.007343"/>
    </inertial>
    <visual>
      <origin rpy="0 0 0" xyz="0 0 0"/>
      <geometry>
        <mesh filename="package://swing_arm/description/meshes/link5.stl"/>
      </geometry>
      <material name="silver"/>
    </visual>
    <collision>
      <origin rpy="0 0 0" xyz="0 0 0"/>
      <geometry>
        <mesh filename="package://swing_arm/description/meshes/link5.stl"/>
      </geometry>
    </collision>
  </link>
  <link name="link6">
    <inertial>
      <origin rpy="0 0 0" xyz="0 0 0"/>
      <mass value="0.070733"/>
      <inertia ixx="1.0630411999999999e-05" ixy="-1.0679999999999999e-16" ixz="8.356999999999999e-05" iyy="0.008414108" iyz="0.0" izz="0.006931832"/>
    </inertial>
    <visual>
      <origin rpy="0 0 0" xyz="0 0 0"/>
      <geometry>
        <mesh filename="package://swing_arm/description/meshes/link6.stl"/>
      </geometry>
      <material name="silver"/>
    </visual>
    <collision>
      <origin rpy="0 0 0" xyz="0 0 0"/>
      <geometry>
        <mesh filename="package://swing_arm/description/meshes/link6.stl"/>
      </geometry>
    </collision>
  </link>
  <joint name="fixed_world" type="fixed">
    <origin rpy="0 0 0" xyz="0 0 0"/>
    <parent link="world"/>
    <child link="base_link"/>
  </joint>
  <joint name="joint1" type="revolute">
    <origin rpy="0 0 0" xyz="0 0 0.07925"/>
    <parent link="base_link"/>
    <child link="link1"/>
    <axis xyz="0 0 1"/>
    <limit effort="150" lower="-1.57" upper="1.57" velocity="1.5"/>
  </joint>
  <joint name="joint2" type="revolute">
    <origin rpy="0 0 0" xyz="0 0 0.0365"/>
    <parent link="link1"/>
    <child link="link2"/>
    <axis xyz="0 1 0"/>
    <limit effort="150" lower="0" upper="1.57" velocity="1.5"/>
  </joint>
  <joint name="joint3" type="revolute">
    <origin rpy="0 0 0" xyz="-0.220 0 0"/>
    <parent link="link2"/>
    <child link="link3"/>
    <axis xyz="0 1 0"/>
    <limit effort="150" lower="-1.57" upper="0" velocity="1.5"/>
  </joint>
  <joint name="joint4" type="revolute">
    <origin rpy="0 0 0" xyz="0.220 0 0.057"/>
    <parent link="link3"/>
    <child link="link4"/>
    <axis xyz="0 1 0"/>
    <limit effort="150" lower="-1.5" upper="0.5" velocity="1.5"/>
  </joint>
  <joint name="joint5" type="revolute">
    <origin rpy="0 0 0" xyz="0.0615 0 0.0825"/>
    <parent link="link4"/>
    <child link="link5"/>
    <axis xyz="0 0 1"/>
    <limit effort="150" lower="-0.785" upper="0.785" velocity="1.5"/>
  </joint>
  <joint name="joint6" type="revolute">
    <origin rpy="0 0 0" xyz="0.0285 0 -0.0825"/>
    <parent link="link5"/>
    <child link="link6"/>
    <axis xyz="1 0 0"/>
    <limit effort="150" lower="-1.57" upper="1.57" velocity="1.5"/>
  </joint>
  <transmission name="joint1_tran">
    <type>transmission_interface/SimpleTransmission</type>
    <joint name="joint1">
      <hardwareInterface>hardware_interface/EffortJointInterface</hardwareInterface>
    </joint>
    <actuator name="joint1_motor">
      <hardwareInterface>hardware_interface/EffortJointInterface</hardwareInterface>
      <mechanicalReduction>1</mechanicalReduction>
    </actuator>
  </transmission>
  <transmission name="joint2_tran">
    <type>transmission_interface/SimpleTransmission</type>
    <joint name="joint2">
      <hardwareInterface>hardware_interface/EffortJointInterface</hardwareInterface>
    </joint>
    <actuator name="joint2_motor">
      <hardwareInterface>hardware_interface/EffortJointInterface</hardwareInterface>
      <mechanicalReduction>-1</mechanicalReduction>
    </actuator>
  </transmission>
  <transmission name="joint3_tran">
    <type>transmission_interface/SimpleTransmission</type>
    <joint name="joint3">
      <hardwareInterface>hardware_interface/EffortJointInterface</hardwareInterface>
    </joint>
    <actuator name="joint3_motor">
      <hardwareInterface>hardware_interface/EffortJointInterface</hardwareInterface>
      <mechanicalReduction>1</mechanicalReduction>
    </actuator>
  </transmission>
  <transmission name="joint4_tran">
    <type>transmission_interface/SimpleTransmission</type>
    <joint name="joint4">
      <hardwareInterface>hardware_interface/EffortJointInterface</hardwareInterface>
    </joint>
    <actuator name="joint4_motor">
      <hardwareInterface>hardware_interface/EffortJointInterface</hardwareInterface>
      <mechanicalReduction>-1</mechanicalReduction>
    </actuator>
  </transmission>
  <transmission name="joint5_tran">
    <type>transmission_interface/SimpleTransmission</type>
    <joint name="joint5">
      <hardwareInterface>hardware_interface/EffortJointInterface</hardwareInterface>
    </joint>
    <actuator name="joint5_motor">
      <hardwareInterface>hardware_interface/EffortJointInterface</hardwareInterface>
      <mechanicalReduction>-1</mechanicalReduction>
    </actuator>
  </transmission>
  <transmission name="joint6_tran">
    <type>transmission_interface/SimpleTransmission</type>
    <joint name="joint6">
      <hardwareInterface>hardware_interface/EffortJointInterface</hardwareInterface>
    </joint>
    <actuator name="joint6_motor">
      <hardwareInterface>hardware_interface/EffortJointInterface</hardwareInterface>
      <mechanicalReduction>1</mechanicalReduction>
    </actuator>
  </transmission>
  <gazebo>
    <plugin filename="libarm_hw_sim.so" name="arm_ros_control">
      <robotNamespace>/</robotNamespace>
      <robotSimType>arm_gazebo/ArmHWSim</robotSimType>
    </plugin>
  </gazebo>
</robot>

